2024-03-02 13:19:53   val set: < MYDATA, satellite_0_thermalmapping_135 - #database: 13011; #queries: 13011 >
2024-03-02 13:19:55   
Traceback (most recent call last):
  File "/home/ningzhang/Documents/project/STGL-local-matching/local_pipeline/evaluatesift.py", line 54, in <module>
    validate_process(args)
  File "/home/ningzhang/anaconda3/envs/ning_gl/lib/python3.10/site-packages/torch/utils/_contextlib.py", line 115, in decorate_context
    return func(*args, **kwargs)
  File "/home/ningzhang/Documents/project/STGL-local-matching/local_pipeline/evaluatesift.py", line 34, in validate_process
    img = inv_base_transforms(image1.detach().cpu())
  File "/home/ningzhang/anaconda3/envs/ning_gl/lib/python3.10/site-packages/torchvision/transforms/transforms.py", line 95, in __call__
    img = t(img)
  File "/home/ningzhang/anaconda3/envs/ning_gl/lib/python3.10/site-packages/torchvision/transforms/transforms.py", line 234, in __call__
    return F.to_pil_image(pic, self.mode)
  File "/home/ningzhang/anaconda3/envs/ning_gl/lib/python3.10/site-packages/torchvision/transforms/functional.py", line 273, in to_pil_image
    raise ValueError(f"pic should be 2/3 dimensional. Got {pic.ndim} dimensions.")
ValueError: pic should be 2/3 dimensional. Got 4 dimensions.

