2024-03-02 11:53:43   val set: < MYDATA, satellite_0_thermalmapping_135 - #database: 13011; #queries: 13011 >
2024-03-02 11:53:45   
Traceback (most recent call last):
  File "/home/ningzhang/Documents/project/STGL-local-matching/local_pipeline/evaluatesift.py", line 51, in <module>
    validate_process(args)
  File "/home/ningzhang/anaconda3/envs/ning_gl/lib/python3.10/site-packages/torch/utils/_contextlib.py", line 115, in decorate_context
    return func(*args, **kwargs)
  File "/home/ningzhang/Documents/project/STGL-local-matching/local_pipeline/evaluatesift.py", line 33, in validate_process
    plt.imshow(image1)
  File "/home/ningzhang/anaconda3/envs/ning_gl/lib/python3.10/site-packages/matplotlib/pyplot.py", line 3343, in imshow
    __ret = gca().imshow(
  File "/home/ningzhang/anaconda3/envs/ning_gl/lib/python3.10/site-packages/matplotlib/__init__.py", line 1465, in inner
    return func(ax, *map(sanitize_sequence, args), **kwargs)
  File "/home/ningzhang/anaconda3/envs/ning_gl/lib/python3.10/site-packages/matplotlib/axes/_axes.py", line 5756, in imshow
    im.set_data(X)
  File "/home/ningzhang/anaconda3/envs/ning_gl/lib/python3.10/site-packages/matplotlib/image.py", line 723, in set_data
    self._A = self._normalize_image_array(A)
  File "/home/ningzhang/anaconda3/envs/ning_gl/lib/python3.10/site-packages/matplotlib/image.py", line 693, in _normalize_image_array
    raise TypeError(f"Invalid shape {A.shape} for image data")
TypeError: Invalid shape (16, 3, 256, 256) for image data

